Workbook

Sheet 📊 Dashboard
B2: Portfolio Optimization — Executive Dashboard
B3: Markowitz Mean-Variance Optimization | Weekly Data 2022–2024 | 14 Stocks: Mega-Cap & High-Volatility Universes
B6: 📌 Portfolio Statistics — Global Minimum Variance Portfolios
B7: Metric | C7: Mega-Cap (7 Stocks) | D7: High-Vol (7 Stocks) | E7: Combined (14 Stocks) | F7: Notes
B8: Expected Return (Weekly) | C8: 0.05284 | D8: -0.013034 | E8: 0.03241 | F8: Weekly log return of GMV portfolio
B9: Portfolio Variance | C9: 0.000913 | D9: 0.0021 | E9: 0.000786 | F9: wᵀΣw — lower is better
B10: Std Deviation (Weekly) | C10: 0.030215 | D10: 0.045822 | E10: 0.028032 | F10: Square root of portfolio variance
B11: Sharpe Ratio | C11: 8.7034 | D11: -11.991 | E11: 14.5705 | F11: As calculated in model (not annualized)
B13: 📐 Optimal Weights — Global Minimum Variance Portfolio
B14: Stock | C14: Universe | D14: Mega-Cap Weight | E14: High-Vol Weight | F14: Combined Weight | G14: Direction
B15: APPLE | C15: Mega-Cap | D15: 0.3642 | E15: — | F15: 0.2998 | G15: Long
B16: NVIDIA | C16: Mega-Cap | D16: -0.1698 | E16: — | F16: -0.1523 | G16: Short
B17: Microsoft | C17: Mega-Cap | D17: 0.7828 | E17: — | F17: 0.6823 | G17: Long
B18: GOOGLE | C18: Mega-Cap | D18: 0.0612 | E18: — | F18: 0.0783 | G18: Long
B19: TESLA | C19: Mega-Cap | D19: -0.0442 | E19: — | F19: -0.0088 | G19: Short
B20: AMAZON | C20: Mega-Cap | D20: 0.0502 | E20: — | F20: 0.0199 | G20: Long
B21: META | C21: Mega-Cap | D21: -0.0444 | E21: — | F21: -0.0307 | G21: Short
B22: SNAP | C22: High-Vol | D22: — | E22: 0.1155 | F22: 0.0431 | G22: Long
B23: CRWD | C23: High-Vol | D23: — | E23: 0.171 | F23: -0.0547 | G23: Short
B24: COIN | C24: High-Vol | D24: — | E24: -0.0978 | F24: -0.0616 | G24: Short
B25: UBER | C25: High-Vol | D25: — | E25: 0.345 | F25: 0.1357 | G25: Long
B26: PLTR | C26: High-Vol | D26: — | E26: 0.0167 | F26: 0.0088 | G26: Long
B27: ROKU | C27: High-Vol | D27: — | E27: -0.0963 | F27: -0.0668 | G27: Short
B28: ZM | C28: High-Vol | D28: — | E28: 0.5461 | F28: 0.1069 | G28: Long
B30: 🔬 Methodology
B31: Return Calculation | C31: Log returns: ln(Pt / Pt-1) applied to weekly price data for all 14 stocks
B32: Excess Return | C32: Excess return = Weekly return minus mean return (avg subtracted via AVERAGE formula in row 203)
B33: Covariance Matrix | C33: 7×7 and 14×14 variance-covariance matrices built from excess return data
B34: Matrix Inverse | C34: MINVERSE applied to covariance matrix to solve for optimal weights
B35: Optimization Target | C35: Global Minimum Variance Portfolio — minimizes portfolio variance subject to weights summing to 1
B36: Short Selling | C36: Permitted — negative weights indicate short positions in the model
B37: Scenario Analysis | C37: Bull case tab: positive returns scaled ×1.2, negative returns scaled ×0.8
B38: Data Period | C38: Jan 2022 – Oct 2025, weekly observations (~130 data points per stock)
B39: Stock Universe 1 | C39: Mega-Cap: APPLE, NVIDIA, Microsoft, GOOGLE, TESLA, AMAZON, META
B40: Stock Universe 2 | C40: High-Volatility: SNAP, CRWD, COIN, UBER, PLTR, ROKU, ZM
B42: 💡 Key Findings
B43: 1. | C43: Combined portfolio achieves the lowest variance (0.000786) — lower than either the mega-cap (0.000913) or high-vol (0.002100) sub-portfolios alone, confirming cross-universe diversification benefits.
B44: 2. | C44: Microsoft dominates the mega-cap optimal portfolio at 78.3% weight — its low variance relative to peers makes it the anchor of the minimum variance solution.
B45: 3. | C45: ZM (54.6%) and UBER (34.5%) carry the highest weights in the high-volatility universe due to their relatively low correlation with other high-vol stocks.
B46: 4. | C46: NVIDIA, TESLA, META (mega-cap) and CRWD, COIN, ROKU (high-vol) all receive negative weights (short positions), indicating they add more risk than return in this sample period.
...

Sheet Data of Top 7 Stocks
A1: Data for Top 7 Stocks
A2: PRICE
A3: Date | B3: APPLE | C3: NVIDIA | D3: Microsoft | E3: GOOGLE | F3: TESLA | G3: AMAZON | H3: META
A4: 44570 | B4: 173.07 | C4: 26.94 | D4: 310.2 | E4: 139.48 | F4: 349.87 | G4: 162.14 | H4: 331.9
A5: 44577 | B5: 162.41 | C5: 23.37 | D5: 296.03 | E5: 130.35 | F5: 314.63 | G5: 142.64 | H5: 303.17
A6: 44584 | B6: 170.33 | C6: 22.84 | D6: 308.26 | E6: 133.35 | F6: 282.12 | G6: 143.98 | H6: 301.71
A7: 44591 | B7: 172.39 | C7: 24.32 | D7: 305.94 | E7: 143.29 | F7: 307.77 | G7: 157.64 | H7: 237.09
A8: 44598 | B8: 168.64 | C8: 23.95 | D8: 295.04 | E8: 134.28 | F8: 286.67 | G8: 153.29 | H8: 219.55
A9: 44605 | B9: 167.3 | C9: 23.64 | D9: 287.93 | E9: 130.4 | F9: 285.66 | G9: 152.6 | H9: 206.16
A10: 44612 | B10: 164.85 | C10: 24.16 | D10: 297.31 | E10: 134.46 | F10: 269.96 | G10: 153.79 | H10: 210.48
A11: 44619 | B11: 163.17 | C11: 22.94 | D11: 289.86 | E11: 131.91 | F11: 279.43 | G11: 145.64 | H11: 200.06
A12: 44626 | B12: 154.73 | C12: 22.1 | D12: 280.07 | E12: 129.87 | F12: 265.12 | G12: 145.52 | H12: 187.61
A13: 44633 | B13: 163.98 | C13: 26.45 | D13: 300.43 | E13: 136.13 | F13: 301.8 | G13: 161.25 | H13: 216.49
A14: 44640 | B14: 174.72 | C14: 27.69 | D14: 303.68 | E14: 141.67 | F14: 336.88 | G14: 164.77 | H14: 221.82
A15: 44647 | B15: 174.31 | C15: 26.71 | D15: 309.42 | E15: 140.15 | F15: 361.53 | G15: 163.56 | H15: 224.85
... A199: 45935 | B199: 245.27 | C199: 183.16 | D199: 510.96 | E199: 236.57 | F199: 413.49 | G199: 216.37 | H199: 705.3
B229: Mean (E®) | D229: S^-1(E®) | F229: Allocated Weigths
B230: 0.001788018 | D230: {=MMULT(_xlfn.ANCHORARRAY(K206),B230:B236)} -> #REF! | F230: =D230/SUM(_xlfn.ANCHORARRAY($D$230)) -> #REF!
B231: 0.0098294765 | F231: =D231/SUM(_xlfn.ANCHORARRAY($D$230)) -> #REF!
B232: 0.0025593541 | F232: =D232/SUM(_xlfn.ANCHORARRAY($D$230)) -> #REF!
B233: 0.0027093483 | F233: =D233/SUM(_xlfn.ANCHORARRAY($D$230)) -> #REF!
B234: 0.00085677781 | F234: =D234/SUM(_xlfn.ANCHORARRAY($D$230)) -> #REF!
B235: 0.0014796397 | F235: =D235/SUM(_xlfn.ANCHORARRAY($D$230)) -> #REF!
B236: 0.0038655873 | F236: =D236/SUM(_xlfn.ANCHORARRAY($D$230)) -> #REF!
E238: Sum | F238: =SUM(F230:F236) -> #REF!
E242: Mean | F242: =SUMPRODUCT(F230:F236,B230:B236) -> #REF!
E243: Variance | F243: {=MMULT(TRANSPOSE(F230:F236),MMULT(_xlfn.ANCHORARRAY(B206),F230:F236))} -> #REF!
E244: Std. deviation | F244: =SQRT(F243) -> #REF!
C247: Sharpie Ratio | E247: =F242/F244 -> #REF!

Sheet Return of Top 7 Stocks
E3: RETURNS | N3: Excess Return
E4: APPLE | F4: NVIDIA | G4: Microsoft | H4: GOOGLE | I4: TESLA | J4: AMAZON | K4: META | N4: APPLE | O4: NVIDIA | P4: Microsoft | Q4: GOOGLE | R4: TESLA | S4: AMAZON | T4: META
E6: =LN('Data of Top 7 Stocks'!B5/'Data of Top 7 Stocks'!B4) -> -0.063572135 | F6: =LN('Data of Top 7 Stocks'!C5/'Data of Top 7 Stocks'!C4) -> -0.14215902 | G6: =LN('Data of Top 7 Stocks'!D5/'Data of Top 7 Stocks'!D4) -> -0.04675645 | H6: =LN('Data of Top 7 Stocks'!E5/'Data of Top 7 Stocks'!E4) -> -0.067698081 | I6: =LN('Data of Top 7 Stocks'!F5/'Data of Top 7 Stocks'!F4) -> -0.10616431 | J6: =LN('Data of Top 7 Stocks'!G5/'Data of Top 7 Stocks'!G4) -> -0.12813619 | K6: =LN('Data of Top 7 Stocks'!H5/'Data of Top 7 Stocks'!H4) -> -0.090540014 | N6: =E6-E$203 -> -0.065360153 | O6: =F6-F$203 -> -0.1519885 | P6: =G6-G$203 -> -0.049315804 | Q6: =H6-H$203 -> -0.07040743 | R6: =I6-I$203 -> -0.10702109 | S6: =J6-J$203 -> -0.12961583 | T6: =K6-K$203 -> -0.094405602
E7: =LN('Data of Top 7 Stocks'!B6/'Data of Top 7 Stocks'!B5) -> 0.04761373 | F7: =LN('Data of Top 7 Stocks'!C6/'Data of Top 7 Stocks'!C5) -> -0.022939764 | G7: =LN('Data of Top 7 Stocks'!D6/'Data of Top 7 Stocks'!D5) -> 0.040482782 | H7: =LN('Data of Top 7 Stocks'!E6/'Data of Top 7 Stocks'!E5) -> 0.02275411 | I7: =LN('Data of Top 7 Stocks'!F6/'Data of Top 7 Stocks'!F5) -> -0.10906483 | J7: =LN('Data of Top 7 Stocks'!G6/'Data of Top 7 Stocks'!G5) -> 0.0093504275 | K7: =LN('Data of Top 7 Stocks'!H6/'Data of Top 7 Stocks'!H5) -> -0.0048274132 | N7: =E7-E$203 -> 0.045825712 | O7: =F7-F$203 -> -0.03276924 | P7: =G7-G$203 -> 0.037923428 | Q7: =H7-H$203 -> 0.020044762 | R7: =I7-I$203 -> -0.10992161 | S7: =J7-J$203 -> 0.0078707878 | T7: =K7-K$203 -> -0.0086930005
E8: =LN('Data of Top 7 Stocks'!B7/'Data of Top 7 Stocks'!B6) -> 0.01202162 | F8: =LN('Data of Top 7 Stocks'!C7/'Data of Top 7 Stocks'!C6) -> 0.062785672 | G8: =LN('Data of Top 7 Stocks'!D7/'Data of Top 7 Stocks'!D6) -> -0.0075545784 | H8: =LN('Data of Top 7 Stocks'!E7/'Data of Top 7 Stocks'!E6) -> 0.071893298 | I8: =LN('Data of Top 7 Stocks'!F7/'Data of Top 7 Stocks'!F6) -> 0.087020238 | J8: =LN('Data of Top 7 Stocks'!G7/'Data of Top 7 Stocks'!G6) -> 0.090639551 | K8: =LN('Data of Top 7 Stocks'!H7/'Data of Top 7 Stocks'!H6) -> -0.24102648 | N8: =E8-E$203 -> 0.010233602 | O8: =F8-F$203 -> 0.052956196 | P8: =G8-G$203 -> -0.010113933 | Q8: =H8-H$203 -> 0.06918395 | R8: =I8-I$203 -> 0.086163461 | S8: =J8-J$203 -> 0.089159912 | T8: =K8-K$203 -> -0.24489206
E9: =LN('Data of Top 7 Stocks'!B8/'Data of Top 7 Stocks'!B7) -> -0.021993087 | F9: =LN('Data of Top 7 Stocks'!C8/'Data of Top 7 Stocks'!C7) -> -0.015330733 | G9: =LN('Data of Top 7 Stocks'!D8/'Data of Top 7 Stocks'!D7) -> -0.036278064 | H9: =LN('Data of Top 7 Stocks'!E8/'Data of Top 7 Stocks'!E7) -> -0.064943377 | I9: =LN('Data of Top 7 Stocks'!F8/'Data of Top 7 Stocks'!F7) -> -0.071021022 | J9: =LN('Data of Top 7 Stocks'!G8/'Data of Top 7 Stocks'!G7) -> -0.0279824 | K9: =LN('Data of Top 7 Stocks'!H8/'Data of Top 7 Stocks'!H7) -> -0.076859819 | N9: =E9-E$203 -> -0.023781105 | O9: =F9-F$203 -> -0.02516021 | P9: =G9-G$203 -> -0.038837418 | Q9: =H9-H$203 -> -0.067652725 | R9: =I9-I$203 -> -0.0718778 | S9: =J9-J$203 -> -0.02946204 | T9: =K9-K$203 -> -0.080725406
E10: =LN('Data of Top 7 Stocks'!B9/'Data of Top 7 Stocks'!B8) -> -0.0079776574 | F10: =LN('Data of Top 7 Stocks'!C9/'Data of Top 7 Stocks'!C8) -> -0.013028131 | G10: =LN('Data of Top 7 Stocks'!D9/'Data of Top 7 Stocks'!D8) -> -0.024393545 | H10: =LN('Data of Top 7 Stocks'!E9/'Data of Top 7 Stocks'!E8) -> -0.029320523 | I10: =LN('Data of Top 7 Stocks'!F9/'Data of Top 7 Stocks'!F8) -> -0.003529436 | J10: =LN('Data of Top 7 Stocks'!G9/'Data of Top 7 Stocks'!G8) -> -0.0045114333 | K10: =LN('Data of Top 7 Stocks'!H9/'Data of Top 7 Stocks'!H8) -> -0.062927431 | N10: =E10-E$203 -> -0.0097656753 | O10: =F10-F$203 -> -0.022857608 | P10: =G10-G$203 -> -0.026952899 | Q10: =H10-H$203 -> -0.032029871 | R10: =I10-I$203 -> -0.0043862138 | S10: =J10-J$203 -> -0.005991073 | T10: =K10-K$203 -> -0.066793018
E11: =LN('Data of Top 7 Stocks'!B10/'Data of Top 7 Stocks'!B9) -> -0.014752638 | F11: =LN('Data of Top 7 Stocks'!C10/'Data of Top 7 Stocks'!C9) -> 0.021758181 | G11: =LN('Data of Top 7 Stocks'!D10/'Data of Top 7 Stocks'!D9) -> 0.03205797 | H11: =LN('Data of Top 7 Stocks'!E10/'Data of Top 7 Stocks'!E9) -> 0.030660108 | I11: =LN('Data of Top 7 Stocks'!F10/'Data of Top 7 Stocks'!F9) -> -0.056528493 | J11: =LN('Data of Top 7 Stocks'!G10/'Data of Top 7 Stocks'!G9) -> 0.0077679166 | K11: =LN('Data of Top 7 Stocks'!H10/'Data of Top 7 Stocks'!H9) -> 0.02073807 | N11: =E11-E$203 -> -0.016540656 | O11: =F11-F$203 -> 0.011928704 | P11: =G11-G$203 -> 0.029498616 | Q11: =H11-H$203 -> 0.027950759 | R11: =I11-I$203 -> -0.05738527 | S11: =J11-J$203 -> 0.0062882769 | T11: =K11-K$203 -> 0.016872483
E12: =LN('Data of Top 7 Stocks'!B11/'Data of Top 7 Stocks'!B10) -> -0.010243367 | F12: =LN('Data of Top 7 Stocks'!C11/'Data of Top 7 Stocks'!C10) -> -0.051816261 | G12: =LN('Data of Top 7 Stocks'!D11/'Data of Top 7 Stocks'!D10) -> -0.025377318 | H12: =LN('Data of Top 7 Stocks'!E11/'Data of Top 7 Stocks'!E10) -> -0.019146885 | I12: =LN('Data of Top 7 Stocks'!F11/'Data of Top 7 Stocks'!F10) -> 0.034478014 | J12: =LN('Data of Top 7 Stocks'!G11/'Data of Top 7 Stocks'!G10) -> -0.054450212 | K12: =LN('Data of Top 7 Stocks'!H11/'Data of Top 7 Stocks'!H10) -> -0.050773315 | N12: =E12-E$203 -> -0.012031385 | O12: =F12-F$203 -> -0.061645738 | P12: =G12-G$203 -> -0.027936672 | Q12: =H12-H$203 -> -0.021856234 | R12: =I12-I$203 -> 0.033621236 | S12: =J12-J$203 -> -0.055929852 | T12: =K12-K$203 -> -0.054638902
E13: =LN('Data of Top 7 Stocks'!B12/'Data of Top 7 Stocks'!B11) -> -0.05311094 | F13: =LN('Data of Top 7 Stocks'!C12/'Data of Top 7 Stocks'!C11) -> -0.037304503 | G13: =LN('Data of Top 7 Stocks'!D12/'Data of Top 7 Stocks'!D11) -> -0.034358476 | H13: =LN('Data of Top 7 Stocks'!E12/'Data of Top 7 Stocks'!E11) -> -0.015585922 | I13: =LN('Data of Top 7 Stocks'!F12/'Data of Top 7 Stocks'!F11) -> -0.05256926 | J13: =LN('Data of Top 7 Stocks'!G12/'Data of Top 7 Stocks'!G11) -> -0.0008242891 | K13: =LN('Data of Top 7 Stocks'!H12/'Data of Top 7 Stocks'!H11) -> -0.064251982 | N13: =E13-E$203 -> -0.054898958 | O13: =F13-F$203 -> -0.04713398 | P13: =G13-G$203 -> -0.03691783 | Q13: =H13-H$203 -> -0.01829527 | R13: =I13-I$203 -> -0.053426038 | S13: =J13-J$203 -> -0.0023039288 | T13: =K13-K$203 -> -0.068117569
E14: =LN('Data of Top 7 Stocks'!B13/'Data of Top 7 Stocks'!B12) -> 0.058062807 | F14: =LN('Data of Top 7 Stocks'!C13/'Data of Top 7 Stocks'!C12) -> 0.17967855 | G14: =LN('Data of Top 7 Stocks'!D13/'Data of Top 7 Stocks'!D12) -> 0.07017521 | H14: =LN('Data of Top 7 Stocks'!E13/'Data of Top 7 Stocks'!E12) -> 0.047076361 | I14: =LN('Data of Top 7 Stocks'!F13/'Data of Top 7 Stocks'!F12) -> 0.12958199 | J14: =LN('Data of Top 7 Stocks'!G13/'Data of Top 7 Stocks'!G12) -> 0.10264242 | K14: =LN('Data of Top 7 Stocks'!H13/'Data of Top 7 Stocks'!H12) -> 0.14317902 | N14: =E14-E$203 -> 0.056274789 | O14: =F14-F$203 -> 0.16984907 | P14: =G14-G$203 -> 0.067615856 | Q14: =H14-H$203 -> 0.044367013 | R14: =I14-I$203 -> 0.12872521 | S14: =J14-J$203 -> 0.10116278 | T14: =K14-K$203 -> 0.13931343
E15: =LN('Data of Top 7 Stocks'!B14/'Data of Top 7 Stocks'!B13) -> 0.063440223 | F15: =LN('Data of Top 7 Stocks'!C14/'Data of Top 7 Stocks'!C13) -> 0.045815179 | G15: =LN('Data of Top 7 Stocks'!D14/'Data of Top 7 Stocks'!D13) -> 0.010759734 | H15: =LN('Data of Top 7 Stocks'!E14/'Data of Top 7 Stocks'!E13) -> 0.039890098 | I15: =LN('Data of Top 7 Stocks'!F14/'Data of Top 7 Stocks'!F13) -> 0.10996224 | J15: =LN('Data of Top 7 Stocks'!G14/'Data of Top 7 Stocks'!G13) -> 0.021594606 | K15: =LN('Data of Top 7 Stocks'!H14/'Data of Top 7 Stocks'!H13) -> 0.024321885 | N15: =E15-E$203 -> 0.061652205 | O15: =F15-F$203 -> 0.035985702 | P15: =G15-G$203 -> 0.0082003795 | Q15: =H15-H$203 -> 0.03718075 | R15: =I15-I$203 -> 0.10910546 | S15: =J15-J$203 -> 0.020114967 | T15: =K15-K$203 -> 0.020456298
E16: =LN('Data of Top 7 Stocks'!B15/'Data of Top 7 Stocks'!B14) -> -0.0023493693 | F16: =LN('Data of Top 7 Stocks'!C15/'Data of Top 7 Stocks'!C14) -> -0.03603331 | G16: =LN('Data of Top 7 Stocks'!D15/'Data of Top 7 Stocks'!D14) -> 0.018725062 | H16: =LN('Data of Top 7 Stocks'!E15/'Data of Top 7 Stocks'!E14) -> -0.010787132 | I16: =LN('Data of Top 7 Stocks'!F15/'Data of Top 7 Stocks'!F14) -> 0.070618242 | J16: =LN('Data of Top 7 Stocks'!G15/'Data of Top 7 Stocks'!G14) -> -0.0073706666 | K16: =LN('Data of Top 7 Stocks'!H15/'Data of Top 7 Stocks'!H14) -> 0.013567271 | N16: =E16-E$203 -> -0.0041373873 | O16: =F16-F$203 -> -0.045862787 | P16: =G16-G$203 -> 0.016165708 | Q16: =H16-H$203 -> -0.01349648 | R16: =I16-I$203 -> 0.069761464 | S16: =J16-J$203 -> -0.0088503063 | T16: =K16-K$203 -> 0.0097016837
E17: =LN('Data of Top 7 Stocks'!B16/'Data of Top 7 Stocks'!B15) -> -0.024507615 | F17: =LN('Data of Top 7 Stocks'!C16/'Data of Top 7 Stocks'!C15) -> -0.14433998 | G17: =LN('Data of Top 7 Stocks'!D16/'Data of Top 7 Stocks'!D15) -> -0.041068454 | H17: =LN('Data of Top 7 Stocks'!E16/'Data of Top 7 Stocks'!E15) -> -0.050186072 | I17: =LN('Data of Top 7 Stocks'!F16/'Data of Top 7 Stocks'!F15) -> -0.056031488 | J17: =LN('Data of Top 7 Stocks'!G16/'Data of Top 7 Stocks'!G15) -> -0.057244732 | K17: =LN('Data of Top 7 Stocks'!H16/'Data of Top 7 Stocks'!H15) -> -0.011270749 | N17: =E17-E$203 -> -0.026295632 | O17: =F17-F$203 -> -0.15416946 | P17: =G17-G$203 -> -0.043627808 | Q17: =H17-H$203 -> -0.05289542 | R17: =I17-I$203 -> -0.056888266 | S17: =J17-J$203 -> -0.058724372 | T17: =K17-K$203 -> -0.015136336
... E200: =LN('Data of Top 7 Stocks'!B199/'Data of Top 7 Stocks'!B198) -> -0.050677457 | F200: =LN('Data of Top 7 Stocks'!C199/'Data of Top 7 Stocks'!C198) -> -0.024058553 | G200: =LN('Data of Top 7 Stocks'!D199/'Data of Top 7 Stocks'!D198) -> -0.012428319 | H200: =LN('Data of Top 7 Stocks'!E199/'Data of Top 7 Stocks'!E198) -> -0.036441615 | I200: =LN('Data of Top 7 Stocks'!F199/'Data of Top 7 Stocks'!F198) -> -0.038756451 | J200: =LN('Data of Top 7 Stocks'!G199/'Data of Top 7 Stocks'!G198) -> -0.014407884 | K200: =LN('Data of Top 7 Stocks'!H199/'Data of Top 7 Stocks'!H198) -> -0.0074301473 | N200: =E200-E$203 -> -0.052465475 | O200: =F200-F$203 -> -0.033888029 | P200: =G200-G$203 -> -0.014987673 | Q200: =H200-H$203 -> -0.039150964 | R200: =I200-I$203 -> -0.039613229 | S200: =J200-J$203 -> -0.015887524 | T200: =K200-K$203 -> -0.011295735
D203: Avg Return | E203: =AVERAGE(E6:E200) -> 0.001788018 | F203: =AVERAGE(F6:F200) -> 0.0098294765 | G203: =AVERAGE(G6:G200) -> 0.0025593541 | H203: =AVERAGE(H6:H200) -> 0.0027093483 | I203: =AVERAGE(I6:I200) -> 0.00085677781 | J203: =AVERAGE(J6:J200) -> 0.0014796397 | K203: =AVERAGE(K6:K200) -> 0.0038655873
E204: Weekly Data | N204: Monthly Data | W204: Yearly Data
E205: APPLE | F205: NVIDIA | G205: Microsoft | H205: GOOGLE | I205: TESLA | J205: AMAZON | K205: META | N205: APPLE | O205: NVIDIA | P205: Microsoft | Q205: GOOGLE | R205: TESLA | S205: AMAZON | T205: META | W205: APPLE | X205: NVIDIA | Y205: Microsoft | Z205: GOOGLE | AA205: TESLA | AB205: AMAZON | AC205: META
D207: Mean | E207: =AVERAGE(E6:E200) -> 0.001788018 | F207: =AVERAGE(F6:F200) -> 0.0098294765 | G207: =AVERAGE(G6:G200) -> 0.0025593541 | H207: =AVERAGE(H6:H200) -> 0.0027093483 | I207: =AVERAGE(I6:I200) -> 0.00085677781 | J207: =AVERAGE(J6:J200) -> 0.0014796397 | K207: =AVERAGE(K6:K200) -> 0.0038655873 | M207: Mean | N207: =E207*4 -> 0.007152072 | O207: =F207*4 -> 0.039317906 | P207: =G207*4 -> 0.010237417 | Q207: =H207*4 -> 0.010837393 | R207: =I207*4 -> 0.0034271113 | S207: =J207*4 -> 0.0059185589 | T207: =K207*4 -> 0.015462349 | V207: Mean | W207: =E207*52 -> 0.092976935 | X207: =F207*52 -> 0.51113278 | Y207: =G207*52 -> 0.13308642 | Z207: =H207*52 -> 0.14088611 | AA207: =I207*52 -> 0.044552446 | AB207: =J207*52 -> 0.076941266 | AC207: =K207*52 -> 0.20101054
D208: Variance | E208: =_xlfn.VAR.S(E6:E200) -> 0.001555022 | F208: =_xlfn.VAR.S(F6:F200) -> 0.0049013338 | G208: =_xlfn.VAR.S(G6:G200) -> 0.0011744357 | H208: =_xlfn.VAR.S(H6:H200) -> 0.0020062447 | I208: =_xlfn.VAR.S(I6:I200) -> 0.0068715595 | J208: =_xlfn.VAR.S(J6:J200) -> 0.0022646222 | K208: =_xlfn.VAR.S(K6:K200) -> 0.0037446711 | M208: Variance | N208: =E208*4 -> 0.0062200878 | O208: =F208*4 -> 0.019605335 | P208: =G208*4 -> 0.0046977426 | Q208: =H208*4 -> 0.0080249788 | R208: =I208*4 -> 0.027486238 | S208: =J208*4 -> 0.009058489 | T208: =K208*4 -> 0.014978684 | V208: Variance | W208: =E208*52 -> 0.080861142 | X208: =F208*52 -> 0.25486936 | Y208: =G208*52 -> 0.061070654 | Z208: =H208*52 -> 0.10432472 | AA208: =I208*52 -> 0.35732109 | AB208: =J208*52 -> 0.11776036 | AC208: =K208*52 -> 0.1947229
D209: Standard Deviation | E209: =SQRT(E208) -> 0.039433767 | F209: =SQRT(F208) -> 0.070009526 | G209: =SQRT(G208) -> 0.03427004 | H209: =SQRT(H208) -> 0.044791123 | I209: =SQRT(I208) -> 0.08289487 | J209: =SQRT(J208) -> 0.047588047 | K209: =SQRT(K208) -> 0.061193718 | M209: Standard Deviation | N209: =E209*4 -> 0.15773507 | O209: =F209*4 -> 0.28003811 | P209: =G209*4 -> 0.13708016 | Q209: =H209*4 -> 0.17916449 | R209: =I209*4 -> 0.33157948 | S209: =J209*4 -> 0.19035219 | T209: =K209*4 -> 0.24477487 | V209: Standard Deviation | W209: =E209*52 -> 2.0505559 | X209: =F209*52 -> 3.6404954 | Y209: =G209*52 -> 1.7820421 | Z209: =H209*52 -> 2.3291384 | AA209: =I209*52 -> 4.3105332 | AB209: =J209*52 -> 2.4745785 | AC209: =K209*52 -> 3.1820733

Sheet Standard Optimum Portfolio
C3: Variance Coveriance Matrix | O3: Matrix Inverse
D4: APPLE | E4: NVIDIA | F4: Microsoft | G4: GOOGLE | H4: TESLA | I4: AMAZON | J4: META | P4: APPLE | Q4: NVIDIA | R4: Microsoft | S4: GOOGLE | T4: TESLA | U4: AMAZON | V4: META
C5: APPLE | D5: {=MMULT(TRANSPOSE('Return of Top 7 Stocks'!N6:T200),'Return of Top 7 Stocks'!N6:T200)/(195-1)} -> 0.001555022 | E5: 0.0013271228 | F5: 0.00073193836 | G5: 0.00099369455 | H5: 0.0015952191 | I5: 0.00096416762 | J5: 0.0008936606 | O5: APPLE | P5: {=MINVERSE(_xlfn.ANCHORARRAY(D5))} -> 1153.9789 | Q5: -62.579473 | R5: -193.29947 | S5: -291.16076 | T5: -129.22965 | U5: -56.793519 | V5: -22.039232
C6: NVIDIA | D6: 0.0013271228 | E6: 0.0049013338 | F6: 0.0016247621 | G6: 0.0014361165 | H6: 0.002639285 | I6: 0.0019675215 | J6: 0.0018025164 | O6: NVIDIA | P6: -62.579473 | Q6: 423.90407 | R6: -401.89366 | S6: 40.732947 | T6: -51.180176 | U6: -132.0244 | V6: -2.9516782
C7: Microsoft | D7: 0.00073193836 | E7: 0.0016247621 | F7: 0.0011744357 | G7: 0.00092737939 | H7: 0.0012199969 | I7: 0.0010806625 | J7: 0.0012203674 | O7: Microsoft | P7: -193.29947 | Q7: -401.89366 | R7: 2400.5348 | S7: -307.68447 | T7: -34.470739 | U7: -298.91168 | V7: -306.78602
C8: GOOGLE | D8: 0.00099369455 | E8: 0.0014361165 | F8: 0.00092737939 | G8: 0.0020062447 | H8: 0.0014658289 | I8: 0.0013394594 | J8: 0.0012672062 | O8: GOOGLE | P8: -291.16076 | Q8: 40.732947 | R8: -307.68447 | S8: 1015.2792 | T8: -20.905612 | U8: -306.82044 | V8: -62.431117
C9: TESLA | D9: 0.0015952191 | E9: 0.002639285 | F9: 0.0012199969 | G9: 0.0014658289 | H9: 0.0068715595 | I9: 0.0017677302 | J9: 0.001119029 | O9: TESLA | P9: -129.22965 | Q9: -51.180176 | R9: -34.470739 | S9: -20.905612 | T9: 216.61349 | U9: -64.502476 | V9: 35.278279
C10: AMAZON | D10: 0.00096416762 | E10: 0.0019675215 | F10: 0.0010806625 | G10: 0.0013394594 | H10: 0.0017677302 | I10: 0.0022646222 | J10: 0.0015224701 | O10: AMAZON | P10: -56.793519 | Q10: -132.0244 | R10: -298.91168 | S10: -306.82044 | T10: -64.502476 | U10: 1038.7606 | V10: -124.70645
C11: META | D11: 0.0008936606 | E11: 0.0018025164 | F11: 0.0012203674 | G11: 0.0012672062 | H11: 0.001119029 | I11: 0.0015224701 | J11: 0.0037446711 | O11: META | P11: -22.039232 | Q11: -2.9516782 | R11: -306.78602 | S11: -62.431117 | T11: 35.278279 | U11: -124.70645 | V11: 434.99286
O13: Vector | P13: 1 | Q13: 1 | R13: 1 | S13: 1 | T13: 1 | U13: 1 | V13: 1
C15: Global Minimum Variance Portfolio
E17: Proportion | F17: {=MMULT(P13:V13,_xlfn.ANCHORARRAY(P5))/SUM(MMULT(P13:V13,_xlfn.ANCHORARRAY(P5)))} -> 0.36415654 | G17: -0.16980267 | H17: 0.78284862 | I17: 0.06117689 | J17: -0.044184179 | K17: 0.050213991 | L17: -0.044409191
E19: Exp Return | F19: =SUMPRODUCT(_xlfn.ANCHORARRAY(F17),'Return of Top 7 Stocks'!W207:AC207) -> 0.05284024
E20: Variance | F20: {=MMULT(_xlfn.ANCHORARRAY(F17),MMULT(_xlfn.ANCHORARRAY(D5),TRANSPOSE(_xlfn.ANCHORARRAY(F17))))} -> 0.000912955
E21: SD | F21: =SQRT(F20) -> 0.030215145
C28: Efficient Portfolio 1
D31: Mean (E®) | F31: S^-1*E® | H31: Allocated Weight
D32: ='Return of Top 7 Stocks'!W207 -> 0.092976935 | F32: {=MMULT(_xlfn.ANCHORARRAY(P5),D32:D38)} -> -5.9964232 | H32: =F32/SUM(_xlfn.ANCHORARRAY($F$32)) -> -0.10360408
D33: ='Return of Top 7 Stocks'!X207 -> 0.51113278 | F33: 150.07329 | H33: =F33/SUM(_xlfn.ANCHORARRAY($F$32)) -> 2.5929133
D34: ='Return of Top 7 Stocks'!Y207 -> 0.13308642 | F34: -33.464941 | H34: =F34/SUM(_xlfn.ANCHORARRAY($F$32)) -> -0.57819543
D35: ='Return of Top 7 Stocks'!Z207 -> 0.14088611 | F35: 58.750966 | H35: =F35/SUM(_xlfn.ANCHORARRAY($F$32)) -> 1.0150784
D36: ='Return of Top 7 Stocks'!AA207 -> 0.044552446 | F36: -33.929075 | H36: =F36/SUM(_xlfn.ANCHORARRAY($F$32)) -> -0.58621457
D37: ='Return of Top 7 Stocks'!AB207 -> 0.076941266 | F37: -103.78781 | H37: =F37/SUM(_xlfn.ANCHORARRAY($F$32)) -> -1.7932091
D38: ='Return of Top 7 Stocks'!AC207 -> 0.20101054 | F38: 26.232243 | H38: =F38/SUM(_xlfn.ANCHORARRAY($F$32)) -> 0.45323143
G40: Total | H40: =SUM(H32:H38) -> 1
E44: Exp Return | F44: =SUMPRODUCT(H32:H38,D32:D38) -> 1.3087659
E45: Variance | F45: {=MMULT(TRANSPOSE(H32:H38),MMULT(_xlfn.ANCHORARRAY(D5),H32:H38))} -> 0.022612395
E46: Std. Deviation | F46: =SQRT(F45) -> 0.15037418
E49: Sharpe Ratio | F49: =F44/F46 -> 8.703395

Sheet Data of High Volatile Stocks 
A1: High Volatile Stocks
A2: Price
A3: Date | B3: SNAP | C3: CRWD | D3: COIN | E3: UBER | F3: PLTR | G3: ROKU | H3: ZM
A4: 44570 | B4: 38.04 | C4: 176.7 | D4: 230.03 | E4: 41.51 | F4: 16.01 | G4: 167.48 | H4: 159.72
A5: 44577 | B5: 32.12 | C5: 164.73 | D5: 191.97 | E5: 35.94 | F5: 13.53 | G5: 152.13 | H5: 147.66
A6: 44584 | B6: 30.42 | C6: 168.9 | D6: 177.58 | E6: 35.21 | F6: 12.71 | G6: 151.23 | H6: 143.81
A7: 44591 | B7: 38.91 | C7: 177.21 | D7: 194.44 | E7: 37.05 | F7: 12.94 | G7: 158.73 | H7: 144.1
A8: 44598 | B8: 39.49 | C8: 181.86 | D8: 194.53 | E8: 35.29 | F8: 13.13 | G8: 163.94 | H8: 141.24
A9: 44605 | B9: 38.01 | C9: 164.93 | D9: 189.16 | E9: 34.68 | F9: 11.02 | G9: 112.46 | H9: 126.96
A10: 44612 | B10: 39.15 | C10: 181.75 | D10: 176.83 | E10: 34.98 | F10: 11.47 | G10: 139.61 | H10: 125.32
A11: 44619 | B11: 33.09 | C11: 179.03 | D11: 165.75 | E11: 29.83 | F11: 10.96 | G11: 121.5 | H11: 108.94
A12: 44626 | B12: 30.05 | C12: 190.54 | D12: 160.07 | E12: 30.76 | F12: 11.39 | G12: 103.85 | H12: 98.12
A13: 44633 | B13: 36 | C13: 208.06 | D13: 185.94 | E13: 33.36 | F13: 12.82 | G13: 124.85 | H13: 116.28
A14: 44640 | B14: 35.4 | C14: 221.95 | D14: 186.71 | E14: 34.06 | F14: 12.97 | G14: 123.75 | H14: 113.93
A15: 44647 | B15: 37.39 | C15: 227.85 | D15: 186.96 | E15: 35.98 | F15: 13.83 | G15: 125.56 | H15: 118.02
... A199: 45935 | B199: 7.78 | C199: 493.66 | D199: 357.01 | E199: 93.4 | F199: 175.44 | G199: 92.02 | H199: 80.28
A245: Combined Portfolio
D248: Returns | S248: Excess Returns
D249: APPLE | E249: NVIDIA | F249: Microsoft | G249: GOOGLE | H249: TESLA | I249: AMAZON | J249: META | K249: SNAP | L249: CRWD | M249: COIN | N249: UBER | O249: PLTR | P249: ROKU | Q249: ZM | S249: APPLE | T249: NVIDIA | U249: Microsoft | V249: GOOGLE | W249: TESLA | X249: AMAZON | Y249: META | Z249: SNAP | AA249: CRWD | AB249: COIN | AC249: UBER | AD249: PLTR | AE249: ROKU | AF249: ZM
D250: NA | E250: NA | F250: NA | G250: NA | H250: NA | I250: NA | J250: NA | K250: NA | L250: NA | M250: NA | N250: NA | O250: NA | P250: NA | Q250: NA
D251: -0.063572135 | E251: -0.14215902 | F251: -0.04675645 | G251: -0.067698081 | H251: -0.10616431 | I251: -0.12813619 | J251: -0.090540014 | K251: -0.16915935 | L251: -0.070145609 | M251: -0.18087063 | N251: -0.14408348 | O251: -0.16830408 | P251: -0.096128523 | Q251: -0.078509949 | S251: =IFERROR(D251-D$448,"NA") -> -0.065360153 | T251: =IFERROR(E251-E$448,"NA") -> -0.1519885 | U251: =IFERROR(F251-F$448,"NA") -> -0.049315804 | V251: =IFERROR(G251-G$448,"NA") -> -0.07040743 | W251: =IFERROR(H251-H$448,"NA") -> -0.10702109 | X251: =IFERROR(I251-I$448,"NA") -> -0.12961583 | Y251: =IFERROR(J251-J$448,"NA") -> -0.094405602 | Z251: =IFERROR(K251-K$448,"NA") -> -0.16102047 | ... AF251: =IFERROR(Q251-Q$448,"NA") -> -0.074982247
D252: 0.04761373 | E252: -0.022939764 | F252: 0.040482782 | G252: 0.02275411 | H252: -0.10906483 | I252: 0.0093504275 | J252: -0.0048274132 | K252: -0.054378602 | L252: 0.024999054 | M252: -0.077917898 | N252: -0.020520748 | O252: -0.062520357 | P252: -0.0059335617 | Q252: -0.02641935 | S252: =IFERROR(D252-D$448,"NA") -> 0.045825712 | T252: =IFERROR(E252-E$448,"NA") -> -0.03276924 | U252: =IFERROR(F252-F$448,"NA") -> 0.037923428 | V252: =IFERROR(G252-G$448,"NA") -> 0.020044762 | W252: =IFERROR(H252-H$448,"NA") -> -0.10992161 | X252: =IFERROR(I252-I$448,"NA") -> 0.0078707878 | Y252: =IFERROR(J252-J$448,"NA") -> -0.0086930005 | Z252: =IFERROR(K252-K$448,"NA") -> -0.046239721 | ... AF252: =IFERROR(Q252-Q$448,"NA") -> -0.022891648
D253: 0.01202162 | E253: 0.062785672 | F253: -0.0075545784 | G253: 0.071893298 | H253: 0.087020238 | I253: 0.090639551 | J253: -0.24102648 | K253: 0.246151 | L253: 0.048028646 | M253: 0.090702421 | N253: 0.050938219 | O253: 0.017934204 | P253: 0.048402789 | Q253: 0.0020145191 | S253: =IFERROR(D253-D$448,"NA") -> 0.010233602 | T253: =IFERROR(E253-E$448,"NA") -> 0.052956196 | U253: =IFERROR(F253-F$448,"NA") -> -0.010113933 | V253: =IFERROR(G253-G$448,"NA") -> 0.06918395 | W253: =IFERROR(H253-H$448,"NA") -> 0.086163461 | X253: =IFERROR(I253-I$448,"NA") -> 0.089159912 | Y253: =IFERROR(J253-J$448,"NA") -> -0.24489206 | Z253: =IFERROR(K253-K$448,"NA") -> 0.25428988 | ... AF253: =IFERROR(Q253-Q$448,"NA") -> 0.0055422204
D254: -0.021993087 | E254: -0.015330733 | F254: -0.036278064 | G254: -0.064943377 | H254: -0.071021022 | I254: -0.0279824 | J254: -0.076859819 | K254: 0.014796188 | L254: 0.02590169 | M254: 0.00046276063 | N254: -0.048668714 | O254: 0.014576399 | P254: 0.032295862 | Q254: -0.020046932 | S254: =IFERROR(D254-D$448,"NA") -> -0.023781105 | T254: =IFERROR(E254-E$448,"NA") -> -0.02516021 | U254: =IFERROR(F254-F$448,"NA") -> -0.038837418 | V254: =IFERROR(G254-G$448,"NA") -> -0.067652725 | W254: =IFERROR(H254-H$448,"NA") -> -0.0718778 | X254: =IFERROR(I254-I$448,"NA") -> -0.02946204 | Y254: =IFERROR(J254-J$448,"NA") -> -0.080725406 | Z254: =IFERROR(K254-K$448,"NA") -> 0.02293507 | ... AF254: =IFERROR(Q254-Q$448,"NA") -> -0.016519231
D255: -0.0079776574 | E255: -0.013028131 | F255: -0.024393545 | G255: -0.029320523 | H255: -0.003529436 | I255: -0.0045114333 | J255: -0.062927431 | K255: -0.038198192 | L255: -0.097716019 | M255: -0.027993175 | N255: -0.017436486 | O255: -0.17518788 | P255: -0.3769029 | Q255: -0.10658849 | S255: =IFERROR(D255-D$448,"NA") -> -0.0097656753 | T255: =IFERROR(E255-E$448,"NA") -> -0.022857608 | U255: =IFERROR(F255-F$448,"NA") -> -0.026952899 | V255: =IFERROR(G255-G$448,"NA") -> -0.032029871 | W255: =IFERROR(H255-H$448,"NA") -> -0.0043862138 | X255: =IFERROR(I255-I$448,"NA") -> -0.005991073 | Y255: =IFERROR(J255-J$448,"NA") -> -0.066793018 | Z255: =IFERROR(K255-K$448,"NA") -> -0.030059311 | ... AF255: =IFERROR(Q255-Q$448,"NA") -> -0.10306079
D256: -0.014752638 | E256: 0.021758181 | F256: 0.03205797 | G256: 0.030660108 | H256: -0.056528493 | I256: 0.0077679166 | J256: 0.02073807 | K256: 0.029551139 | L256: 0.097110975 | M256: -0.067404399 | N256: 0.0086133177 | O256: 0.040023127 | P256: 0.21625522 | Q256: -0.01300161 | S256: =IFERROR(D256-D$448,"NA") -> -0.016540656 | T256: =IFERROR(E256-E$448,"NA") -> 0.011928704 | U256: =IFERROR(F256-F$448,"NA") -> 0.029498616 | V256: =IFERROR(G256-G$448,"NA") -> 0.027950759 | W256: =IFERROR(H256-H$448,"NA") -> -0.05738527 | X256: =IFERROR(I256-I$448,"NA") -> 0.0062882769 | Y256: =IFERROR(J256-J$448,"NA") -> 0.016872483 | Z256: =IFERROR(K256-K$448,"NA") -> 0.037690021 | ... AF256: =IFERROR(Q256-Q$448,"NA") -> -0.0094739088
D257: -0.010243367 | E257: -0.051816261 | F257: -0.025377318 | G257: -0.019146885 | H257: 0.034478014 | I257: -0.054450212 | J257: -0.050773315 | K257: -0.1681693 | L257: -0.015078727 | M257: -0.06470819 | N257: -0.15926187 | O257: -0.04548265 | P257: -0.13893856 | Q257: -0.14007319 | S257: =IFERROR(D257-D$448,"NA") -> -0.012031385 | T257: =IFERROR(E257-E$448,"NA") -> -0.061645738 | U257: =IFERROR(F257-F$448,"NA") -> -0.027936672 | V257: =IFERROR(G257-G$448,"NA") -> -0.021856234 | W257: =IFERROR(H257-H$448,"NA") -> 0.033621236 | X257: =IFERROR(I257-I$448,"NA") -> -0.055929852 | Y257: =IFERROR(J257-J$448,"NA") -> -0.054638902 | Z257: =IFERROR(K257-K$448,"NA") -> -0.16003042 | ... AF257: =IFERROR(Q257-Q$448,"NA") -> -0.13654549
D258: -0.05311094 | E258: -0.037304503 | F258: -0.034358476 | G258: -0.015585922 | H258: -0.05256926 | I258: -0.0008242891 | J258: -0.064251982 | K258: -0.096368461 | L258: 0.062308757 | M258: -0.03486941 | N258: 0.030700546 | O258: 0.038483496 | P258: -0.15696671 | Q258: -0.10460605 | S258: =IFERROR(D258-D$448,"NA") -> -0.054898958 | T258: =IFERROR(E258-E$448,"NA") -> -0.04713398 | U258: =IFERROR(F258-F$448,"NA") -> -0.03691783 | V258: =IFERROR(G258-G$448,"NA") -> -0.01829527 | W258: =IFERROR(H258-H$448,"NA") -> -0.053426038 | X258: =IFERROR(I258-I$448,"NA") -> -0.0023039288 | Y258: =IFERROR(J258-J$448,"NA") -> -0.068117569 | Z258: =IFERROR(K258-K$448,"NA") -> -0.088229579 | ... AF258: =IFERROR(Q258-Q$448,"NA") -> -0.10107835
D259: 0.058062807 | E259: 0.17967855 | F259: 0.07017521 | G259: 0.047076361 | H259: 0.12958199 | I259: 0.10264242 | J259: 0.14317902 | K259: 0.18065628 | L259: 0.087964353 | M259: 0.14981282 | N259: 0.081142433 | O259: 0.11827067 | P259: 0.18416547 | Q259: 0.16980986 | S259: =IFERROR(D259-D$448,"NA") -> 0.056274789 | T259: =IFERROR(E259-E$448,"NA") -> 0.16984907 | U259: =IFERROR(F259-F$448,"NA") -> 0.067615856 | V259: =IFERROR(G259-G$448,"NA") -> 0.044367013 | W259: =IFERROR(H259-H$448,"NA") -> 0.12872521 | X259: =IFERROR(I259-I$448,"NA") -> 0.10116278 | Y259: =IFERROR(J259-J$448,"NA") -> 0.13931343 | Z259: =IFERROR(K259-K$448,"NA") -> 0.18879516 | ... AF259: =IFERROR(Q259-Q$448,"NA") -> 0.17333756
D260: 0.063440223 | E260: 0.045815179 | F260: 0.010759734 | G260: 0.039890098 | H260: 0.10996224 | I260: 0.021594606 | J260: 0.024321885 | K260: -0.016807118 | L260: 0.064625632 | M260: 0.0041325699 | N260: 0.020766098 | O260: 0.011632547 | P260: -0.0088496153 | Q260: -0.020416851 | S260: =IFERROR(D260-D$448,"NA") -> 0.061652205 | T260: =IFERROR(E260-E$448,"NA") -> 0.035985702 | U260: =IFERROR(F260-F$448,"NA") -> 0.0082003795 | V260: =IFERROR(G260-G$448,"NA") -> 0.03718075 | W260: =IFERROR(H260-H$448,"NA") -> 0.10910546 | X260: =IFERROR(I260-I$448,"NA") -> 0.020114967 | Y260: =IFERROR(J260-J$448,"NA") -> 0.020456298 | Z260: =IFERROR(K260-K$448,"NA") -> -0.0086682368 | ... AF260: =IFERROR(Q260-Q$448,"NA") -> -0.01688915
D261: -0.0023493693 | E261: -0.03603331 | F261: 0.018725062 | G261: -0.010787132 | H261: 0.070618242 | I261: -0.0073706666 | J261: 0.013567271 | K261: 0.054691469 | L261: 0.026235386 | M261: 0.0013380793 | N261: 0.054839553 | O261: 0.064201147 | P261: 0.014520331 | Q261: 0.035269877 | S261: =IFERROR(D261-D$448,"NA") -> -0.0041373873 | T261: =IFERROR(E261-E$448,"NA") -> -0.045862787 | U261: =IFERROR(F261-F$448,"NA") -> 0.016165708 | V261: =IFERROR(G261-G$448,"NA") -> -0.01349648 | W261: =IFERROR(H261-H$448,"NA") -> 0.069761464 | X261: =IFERROR(I261-I$448,"NA") -> -0.0088503063 | Y261: =IFERROR(J261-J$448,"NA") -> 0.0097016837 | Z261: =IFERROR(K261-K$448,"NA") -> 0.06283035 | ... AF261: =IFERROR(Q261-Q$448,"NA") -> 0.038797578
D262: -0.024507615 | E262: -0.14433998 | F262: -0.041068454 | G262: -0.050186072 | H262: -0.056031488 | I262: -0.057244732 | J262: -0.011270749 | K262: -0.04709329 | L262: -0.043229616 | M262: -0.14986307 | N262: -0.11566605 | O262: -0.085238152 | P262: -0.090115033 | Q262: -0.062225207 | S262: =IFERROR(D262-D$448,"NA") -> -0.026295632 | T262: =IFERROR(E262-E$448,"NA") -> -0.15416946 | U262: =IFERROR(F262-F$448,"NA") -> -0.043627808 | V262: =IFERROR(G262-G$448,"NA") -> -0.05289542 | W262: =IFERROR(H262-H$448,"NA") -> -0.056888266 | X262: =IFERROR(I262-I$448,"NA") -> -0.058724372 | Y262: =IFERROR(J262-J$448,"NA") -> -0.015136336 | Z262: =IFERROR(K262-K$448,"NA") -> -0.038954408 | ... AF262: =IFERROR(Q262-Q$448,"NA") -> -0.058697506
... D445: -0.050677457 | E445: -0.024058553 | F445: -0.012428319 | G445: -0.036441615 | H445: -0.038756451 | I445: -0.014407884 | J445: -0.0074301473 | K445: -0.09320467 | L445: 0.007686558 | M445: -0.06246009 | N445: -0.033687396 | O445: 0.013600967 | P445: -0.12094161 | Q445: -0.0084346816 | S445: =IFERROR(D445-D$448,"NA") -> -0.052465475 | T445: =IFERROR(E445-E$448,"NA") -> -0.033888029 | U445: =IFERROR(F445-F$448,"NA") -> -0.014987673 | V445: =IFERROR(G445-G$448,"NA") -> -0.039150964 | W445: =IFERROR(H445-H$448,"NA") -> -0.039613229 | X445: =IFERROR(I445-I$448,"NA") -> -0.015887524 | Y445: =IFERROR(J445-J$448,"NA") -> -0.011295735 | Z445: =IFERROR(K445-K$448,"NA") -> -0.085065788 | ... AF445: =IFERROR(Q445-Q$448,"NA") -> -0.0049069803
C448: Mean | D448: =AVERAGE(D250:D445) -> 0.001788018 | E448: =AVERAGE(E250:E445) -> 0.0098294765 | F448: =AVERAGE(F250:F445) -> 0.0025593541 | G448: =AVERAGE(G250:G445) -> 0.0027093483 | H448: =AVERAGE(H250:H445) -> 0.00085677781 | I448: =AVERAGE(I250:I445) -> 0.0014796397 | J448: =AVERAGE(J250:J445) -> 0.0038655873 | K448: =AVERAGE(K250:K445) -> -0.0081388815 | ... Q448: =AVERAGE(Q250:Q445) -> -0.0035277013
C452: Variance Covariance Matrix | S452: Matrix Inverse
C453: APPLE | D453: NVIDIA | E453: Microsoft | F453: GOOGLE | G453: TESLA | H453: AMAZON | I453: META | J453: SNAP | K453: CRWD | L453: COIN | M453: UBER | N453: PLTR | O453: ROKU | P453: ZM | S453: APPLE | T453: NVIDIA | U453: Microsoft | V453: GOOGLE | W453: TESLA | X453: AMAZON | Y453: META | Z453: SNAP | AA453: CRWD | AB453: COIN | AC453: UBER | AD453: PLTR | AE453: ROKU | AF453: ZM
B454: APPLE | C454: {=MMULT(TRANSPOSE(S251:AF445),S251:AF445)/(195-1)} -> 0.001555022 | D454: 0.0013271228 | E454: 0.00073193836 | F454: 0.00099369455 | G454: 0.0015952191 | H454: 0.00096416762 | I454: 0.0008936606 | J454: 0.00088699317 | K454: 0.0011642862 | L454: 0.0019189196 | M454: 0.0008440183 | N454: 0.0013833051 | O454: 0.0017947577 | P454: 0.00096854881 | R454: APPLE | S454: {=MINVERSE(_xlfn.ANCHORARRAY(C454))} -> 1217.7245 | T454: -46.982916 | U454: -205.03189 | V454: -286.6689 | W454: -142.09732 | X454: -35.640189 | Y454: 8.905645 | Z454: 10.714757 | AA454: -28.894993 | AB454: 21.107443 | AC454: -60.115928 | AD454: 57.310383 | AE454: -76.658193 | AF454: -52.185963
B455: NVIDIA | C455: 0.0013271228 | D455: 0.0049013338 | E455: 0.0016247621 | F455: 0.0014361165 | G455: 0.002639285 | H455: 0.0019675215 | I455: 0.0018025164 | J455: 0.0017558338 | K455: 0.0025179258 | L455: 0.0044075716 | M455: 0.0020872362 | N455: 0.0034933286 | O455: 0.0031054125 | P455: 0.0016791968 | R455: NVIDIA | S455: -46.982916 | T455: 476.75108 | U455: -419.87597 | V455: 47.220415 | W455: -33.382398 | X455: -63.17326 | Y455: 11.19126 | Z455: -14.470596 | AA455: -19.253136 | AB455: -13.191315 | AC455: -71.770646 | AD455: -52.754654 | AE455: -8.0697122 | AF455: 13.951578
B456: Microsoft | C456: 0.00073193836 | D456: 0.0016247621 | E456: 0.0011744357 | F456: 0.00092737939 | G456: 0.0012199969 | H456: 0.0010806625 | I456: 0.0012203674 | J456: 0.00074103176 | K456: 0.0012524328 | L456: 0.001948415 | M456: 0.00083876755 | N456: 0.0014271644 | O456: 0.001401944 | P456: 0.00084476782 | R456: Microsoft | S456: -205.03189 | T456: -419.87597 | U456: 2474.121 | V456: -310.65715 | W456: -33.858148 | X456: -296.95433 | Y456: -325.07516 | Z456: 38.027697 | AA456: -127.85874 | AB456: -17.89085 | AC456: 46.488226 | AD456: 49.360415 | AE456: 59.343559 | AF456: -61.82202
B457: GOOGLE | C457: 0.00099369455 | D457: 0.0014361165 | E457: 0.00092737939 | F457: 0.0020062447 | G457: 0.0014658289 | H457: 0.0013394594 | I457: 0.0012672062 | J457: 0.0012628897 | K457: 0.0014253139 | L457: 0.0022999812 | M457: 0.00078200912 | N457: 0.0017282905 | O457: 0.0019446031 | P457: 0.001081156 | R457: GOOGLE | S457: -286.6689 | T457: 47.220415 | U457: -310.65715 | V457: 1068.1534 | W457: 6.0191348 | X457: -293.90451 | Y457: -64.090318 | Z457: -39.447522 | AA457: -30.260643 | AB457: -9.5760723 | AC457: 112.38326 | AD457: -28.035688 | AE457: -21.878795 | AF457: -49.649383
...

Sheet Return of volatile stocks
E4: Return | N4: Excess Return
E5: SNAP | F5: CRWD | G5: COIN | H5: UBER | I5: PLTR | J5: ROKU | K5: ZM | N5: SNAP | O5: CRWD | P5: COIN | Q5: UBER | R5: PLTR | S5: ROKU | T5: ZM
E6: =LN('Data of High Volatile Stocks '!B5/'Data of High Volatile Stocks '!B4) -> -0.16915935 | F6: =LN('Data of High Volatile Stocks '!C5/'Data of High Volatile Stocks '!C4) -> -0.070145609 | G6: =LN('Data of High Volatile Stocks '!D5/'Data of High Volatile Stocks '!D4) -> -0.18087063 | H6: =LN('Data of High Volatile Stocks '!E5/'Data of High Volatile Stocks '!E4) -> -0.14408348 | I6: =LN('Data of High Volatile Stocks '!F5/'Data of High Volatile Stocks '!F4) -> -0.16830408 | J6: =LN('Data of High Volatile Stocks '!G5/'Data of High Volatile Stocks '!G4) -> -0.096128523 | K6: =LN('Data of High Volatile Stocks '!H5/'Data of High Volatile Stocks '!H4) -> -0.078509949 | N6: =E6-E$202 -> -0.16102047 | O6: =F6-F$202 -> -0.075414295 | P6: =G6-G$202 -> -0.18312475 | Q6: =H6-H$202 -> -0.14824223 | R6: =I6-I$202 -> -0.18058144 | S6: =J6-J$202 -> -0.093057456 | T6: =K6-K$202 -> -0.074982247
E7: =LN('Data of High Volatile Stocks '!B6/'Data of High Volatile Stocks '!B5) -> -0.054378602 | F7: =LN('Data of High Volatile Stocks '!C6/'Data of High Volatile Stocks '!C5) -> 0.024999054 | G7: =LN('Data of High Volatile Stocks '!D6/'Data of High Volatile Stocks '!D5) -> -0.077917898 | H7: =LN('Data of High Volatile Stocks '!E6/'Data of High Volatile Stocks '!E5) -> -0.020520748 | I7: =LN('Data of High Volatile Stocks '!F6/'Data of High Volatile Stocks '!F5) -> -0.062520357 | J7: =LN('Data of High Volatile Stocks '!G6/'Data of High Volatile Stocks '!G5) -> -0.0059335617 | K7: =LN('Data of High Volatile Stocks '!H6/'Data of High Volatile Stocks '!H5) -> -0.02641935 | N7: =E7-E$202 -> -0.046239721 | O7: =F7-F$202 -> 0.019730369 | P7: =G7-G$202 -> -0.080172022 | Q7: =H7-H$202 -> -0.024679502 | R7: =I7-I$202 -> -0.074797709 | S7: =J7-J$202 -> -0.0028624951 | T7: =K7-K$202 -> -0.022891648
E8: =LN('Data of High Volatile Stocks '!B7/'Data of High Volatile Stocks '!B6) -> 0.246151 | F8: =LN('Data of High Volatile Stocks '!C7/'Data of High Volatile Stocks '!C6) -> 0.048028646 | G8: =LN('Data of High Volatile Stocks '!D7/'Data of High Volatile Stocks '!D6) -> 0.090702421 | H8: =LN('Data of High Volatile Stocks '!E7/'Data of High Volatile Stocks '!E6) -> 0.050938219 | I8: =LN('Data of High Volatile Stocks '!F7/'Data of High Volatile Stocks '!F6) -> 0.017934204 | J8: =LN('Data of High Volatile Stocks '!G7/'Data of High Volatile Stocks '!G6) -> 0.048402789 | K8: =LN('Data of High Volatile Stocks '!H7/'Data of High Volatile Stocks '!H6) -> 0.0020145191 | N8: =E8-E$202 -> 0.25428988 | O8: =F8-F$202 -> 0.042759961 | P8: =G8-G$202 -> 0.088448297 | Q8: =H8-H$202 -> 0.046779465 | R8: =I8-I$202 -> 0.0056568522 | S8: =J8-J$202 -> 0.051473855 | T8: =K8-K$202 -> 0.0055422204
E9: =LN('Data of High Volatile Stocks '!B8/'Data of High Volatile Stocks '!B7) -> 0.014796188 | F9: =LN('Data of High Volatile Stocks '!C8/'Data of High Volatile Stocks '!C7) -> 0.02590169 | G9: =LN('Data of High Volatile Stocks '!D8/'Data of High Volatile Stocks '!D7) -> 0.00046276063 | H9: =LN('Data of High Volatile Stocks '!E8/'Data of High Volatile Stocks '!E7) -> -0.048668714 | I9: =LN('Data of High Volatile Stocks '!F8/'Data of High Volatile Stocks '!F7) -> 0.014576399 | J9: =LN('Data of High Volatile Stocks '!G8/'Data of High Volatile Stocks '!G7) -> 0.032295862 | K9: =LN('Data of High Volatile Stocks '!H8/'Data of High Volatile Stocks '!H7) -> -0.020046932 | N9: =E9-E$202 -> 0.02293507 | O9: =F9-F$202 -> 0.020633005 | P9: =G9-G$202 -> -0.0017913627 | Q9: =H9-H$202 -> -0.052827468 | R9: =I9-I$202 -> 0.0022990476 | S9: =J9-J$202 -> 0.035366928 | T9: =K9-K$202 -> -0.016519231
E10: =LN('Data of High Volatile Stocks '!B9/'Data of High Volatile Stocks '!B8) -> -0.038198192 | F10: =LN('Data of High Volatile Stocks '!C9/'Data of High Volatile Stocks '!C8) -> -0.097716019 | G10: =LN('Data of High Volatile Stocks '!D9/'Data of High Volatile Stocks '!D8) -> -0.027993175 | H10: =LN('Data of High Volatile Stocks '!E9/'Data of High Volatile Stocks '!E8) -> -0.017436486 | I10: =LN('Data of High Volatile Stocks '!F9/'Data of High Volatile Stocks '!F8) -> -0.17518788 | J10: =LN('Data of High Volatile Stocks '!G9/'Data of High Volatile Stocks '!G8) -> -0.3769029 | K10: =LN('Data of High Volatile Stocks '!H9/'Data of High Volatile Stocks '!H8) -> -0.10658849 | N10: =E10-E$202 -> -0.030059311 | O10: =F10-F$202 -> -0.1029847 | P10: =G10-G$202 -> -0.030247298 | Q10: =H10-H$202 -> -0.02159524 | R10: =I10-I$202 -> -0.18746524 | S10: =J10-J$202 -> -0.37383184 | T10: =K10-K$202 -> -0.10306079
E11: =LN('Data of High Volatile Stocks '!B10/'Data of High Volatile Stocks '!B9) -> 0.029551139 | F11: =LN('Data of High Volatile Stocks '!C10/'Data of High Volatile Stocks '!C9) -> 0.097110975 | G11: =LN('Data of High Volatile Stocks '!D10/'Data of High Volatile Stocks '!D9) -> -0.067404399 | H11: =LN('Data of High Volatile Stocks '!E10/'Data of High Volatile Stocks '!E9) -> 0.0086133177 | I11: =LN('Data of High Volatile Stocks '!F10/'Data of High Volatile Stocks '!F9) -> 0.040023127 | J11: =LN('Data of High Volatile Stocks '!G10/'Data of High Volatile Stocks '!G9) -> 0.21625522 | K11: =LN('Data of High Volatile Stocks '!H10/'Data of High Volatile Stocks '!H9) -> -0.01300161 | N11: =E11-E$202 -> 0.037690021 | O11: =F11-F$202 -> 0.09184229 | P11: =G11-G$202 -> -0.069658522 | Q11: =H11-H$202 -> 0.0044545639 | R11: =I11-I$202 -> 0.027745776 | S11: =J11-J$202 -> 0.21932628 | T11: =K11-K$202 -> -0.0094739088
E12: =LN('Data of High Volatile Stocks '!B11/'Data of High Volatile Stocks '!B10) -> -0.1681693 | F12: =LN('Data of High Volatile Stocks '!C11/'Data of High Volatile Stocks '!C10) -> -0.015078727 | G12: =LN('Data of High Volatile Stocks '!D11/'Data of High Volatile Stocks '!D10) -> -0.06470819 | H12: =LN('Data of High Volatile Stocks '!E11/'Data of High Volatile Stocks '!E10) -> -0.15926187 | I12: =LN('Data of High Volatile Stocks '!F11/'Data of High Volatile Stocks '!F10) -> -0.04548265 | J12: =LN('Data of High Volatile Stocks '!G11/'Data of High Volatile Stocks '!G10) -> -0.13893856 | K12: =LN('Data of High Volatile Stocks '!H11/'Data of High Volatile Stocks '!H10) -> -0.14007319 | N12: =E12-E$202 -> -0.16003042 | O12: =F12-F$202 -> -0.020347412 | P12: =G12-G$202 -> -0.066962313 | Q12: =H12-H$202 -> -0.16342062 | R12: =I12-I$202 -> -0.057760001 | S12: =J12-J$202 -> -0.13586749 | T12: =K12-K$202 -> -0.13654549
E13: =LN('Data of High Volatile Stocks '!B12/'Data of High Volatile Stocks '!B11) -> -0.096368461 | F13: =LN('Data of High Volatile Stocks '!C12/'Data of High Volatile Stocks '!C11) -> 0.062308757 | G13: =LN('Data of High Volatile Stocks '!D12/'Data of High Volatile Stocks '!D11) -> -0.03486941 | H13: =LN('Data of High Volatile Stocks '!E12/'Data of High Volatile Stocks '!E11) -> 0.030700546 | I13: =LN('Data of High Volatile Stocks '!F12/'Data of High Volatile Stocks '!F11) -> 0.038483496 | J13: =LN('Data of High Volatile Stocks '!G12/'Data of High Volatile Stocks '!G11) -> -0.15696671 | K13: =LN('Data of High Volatile Stocks '!H12/'Data of High Volatile Stocks '!H11) -> -0.10460605 | N13: =E13-E$202 -> -0.088229579 | O13: =F13-F$202 -> 0.057040071 | P13: =G13-G$202 -> -0.037123533 | Q13: =H13-H$202 -> 0.026541792 | R13: =I13-I$202 -> 0.026206144 | S13: =J13-J$202 -> -0.15389565 | T13: =K13-K$202 -> -0.10107835
E14: =LN('Data of High Volatile Stocks '!B13/'Data of High Volatile Stocks '!B12) -> 0.18065628 | F14: =LN('Data of High Volatile Stocks '!C13/'Data of High Volatile Stocks '!C12) -> 0.087964353 | G14: =LN('Data of High Volatile Stocks '!D13/'Data of High Volatile Stocks '!D12) -> 0.14981282 | H14: =LN('Data of High Volatile Stocks '!E13/'Data of High Volatile Stocks '!E12) -> 0.081142433 | I14: =LN('Data of High Volatile Stocks '!F13/'Data of High Volatile Stocks '!F12) -> 0.11827067 | J14: =LN('Data of High Volatile Stocks '!G13/'Data of High Volatile Stocks '!G12) -> 0.18416547 | K14: =LN('Data of High Volatile Stocks '!H13/'Data of High Volatile Stocks '!H12) -> 0.16980986 | N14: =E14-E$202 -> 0.18879516 | O14: =F14-F$202 -> 0.082695668 | P14: =G14-G$202 -> 0.1475587 | Q14: =H14-H$202 -> 0.076983679 | R14: =I14-I$202 -> 0.10599332 | S14: =J14-J$202 -> 0.18723653 | T14: =K14-K$202 -> 0.17333756
E15: =LN('Data of High Volatile Stocks '!B14/'Data of High Volatile Stocks '!B13) -> -0.016807118 | F15: =LN('Data of High Volatile Stocks '!C14/'Data of High Volatile Stocks '!C13) -> 0.064625632 | G15: =LN('Data of High Volatile Stocks '!D14/'Data of High Volatile Stocks '!D13) -> 0.0041325699 | H15: =LN('Data of High Volatile Stocks '!E14/'Data of High Volatile Stocks '!E13) -> 0.020766098 | I15: =LN('Data of High Volatile Stocks '!F14/'Data of High Volatile Stocks '!F13) -> 0.011632547 | J15: =LN('Data of High Volatile Stocks '!G14/'Data of High Volatile Stocks '!G13) -> -0.0088496153 | K15: =LN('Data of High Volatile Stocks '!H14/'Data of High Volatile Stocks '!H13) -> -0.020416851 | N15: =E15-E$202 -> -0.0086682368 | O15: =F15-F$202 -> 0.059356946 | P15: =G15-G$202 -> 0.0018784466 | Q15: =H15-H$202 -> 0.016607344 | R15: =I15-I$202 -> -0.00064480484 | S15: =J15-J$202 -> -0.0057785486 | T15: =K15-K$202 -> -0.01688915
E16: =LN('Data of High Volatile Stocks '!B15/'Data of High Volatile Stocks '!B14) -> 0.054691469 | F16: =LN('Data of High Volatile Stocks '!C15/'Data of High Volatile Stocks '!C14) -> 0.026235386 | G16: =LN('Data of High Volatile Stocks '!D15/'Data of High Volatile Stocks '!D14) -> 0.0013380793 | H16: =LN('Data of High Volatile Stocks '!E15/'Data of High Volatile Stocks '!E14) -> 0.054839553 | I16: =LN('Data of High Volatile Stocks '!F15/'Data of High Volatile Stocks '!F14) -> 0.064201147 | J16: =LN('Data of High Volatile Stocks '!G15/'Data of High Volatile Stocks '!G14) -> 0.014520331 | K16: =LN('Data of High Volatile Stocks '!H15/'Data of High Volatile Stocks '!H14) -> 0.035269877 | N16: =E16-E$202 -> 0.06283035 | O16: =F16-F$202 -> 0.020966701 | P16: =G16-G$202 -> -0.00091604412 | Q16: =H16-H$202 -> 0.0506808 | R16: =I16-I$202 -> 0.051923796 | S16: =J16-J$202 -> 0.017591397 | T16: =K16-K$202 -> 0.038797578
E17: =LN('Data of High Volatile Stocks '!B16/'Data of High Volatile Stocks '!B15) -> -0.04709329 | F17: =LN('Data of High Volatile Stocks '!C16/'Data of High Volatile Stocks '!C15) -> -0.043229616 | G17: =LN('Data of High Volatile Stocks '!D16/'Data of High Volatile Stocks '!D15) -> -0.14986307 | H17: =LN('Data of High Volatile Stocks '!E16/'Data of High Volatile Stocks '!E15) -> -0.11566605 | I17: =LN('Data of High Volatile Stocks '!F16/'Data of High Volatile Stocks '!F15) -> -0.085238152 | J17: =LN('Data of High Volatile Stocks '!G16/'Data of High Volatile Stocks '!G15) -> -0.090115033 | K17: =LN('Data of High Volatile Stocks '!H16/'Data of High Volatile Stocks '!H15) -> -0.062225207 | N17: =E17-E$202 -> -0.038954408 | O17: =F17-F$202 -> -0.048498301 | P17: =G17-G$202 -> -0.15211719 | Q17: =H17-H$202 -> -0.1198248 | R17: =I17-I$202 -> -0.097515504 | S17: =J17-J$202 -> -0.087043966 | T17: =K17-K$202 -> -0.058697506
... E200: =LN('Data of High Volatile Stocks '!B199/'Data of High Volatile Stocks '!B198) -> -0.09320467 | F200: =LN('Data of High Volatile Stocks '!C199/'Data of High Volatile Stocks '!C198) -> 0.007686558 | G200: =LN('Data of High Volatile Stocks '!D199/'Data of High Volatile Stocks '!D198) -> -0.06246009 | H200: =LN('Data of High Volatile Stocks '!E199/'Data of High Volatile Stocks '!E198) -> -0.033687396 | I200: =LN('Data of High Volatile Stocks '!F199/'Data of High Volatile Stocks '!F198) -> 0.013600967 | J200: =LN('Data of High Volatile Stocks '!G199/'Data of High Volatile Stocks '!G198) -> -0.12094161 | K200: =LN('Data of High Volatile Stocks '!H199/'Data of High Volatile Stocks '!H198) -> -0.0084346816 | N200: =E200-E$202 -> -0.085065788 | O200: =F200-F$202 -> 0.0024178726 | P200: =G200-G$202 -> -0.064714214 | Q200: =H200-H$202 -> -0.03784615 | R200: =I200-I$202 -> 0.0013236155 | S200: =J200-J$202 -> -0.11787054 | T200: =K200-K$202 -> -0.0049069803
D202: Mean | E202: =AVERAGE(E6:E200) -> -0.0081388815 | F202: =AVERAGE(F6:F200) -> 0.0052686853 | G202: =AVERAGE(G6:G200) -> 0.0022541234 | H202: =AVERAGE(H6:H200) -> 0.0041587538 | I202: =AVERAGE(I6:I200) -> 0.012277352 | J202: =AVERAGE(J6:J200) -> -0.0030710666 | K202: =AVERAGE(K6:K200) -> -0.0035277013
E205: Weekly Data | N205: Monthly Data | W205: Yearly Data
E206: SNAP | F206: CRWD | G206: COIN | H206: UBER | I206: PLTR | J206: ROKU | K206: ZM | N206: SNAP | O206: CRWD | P206: COIN | Q206: UBER | R206: PLTR | S206: ROKU | T206: ZM | W206: SNAP | X206: CRWD | Y206: COIN | Z206: UBER | AA206: PLTR | AB206: ROKU | AC206: ZM
D207: Return | E207: =AVERAGE(E6:E200) -> -0.0081388815 | F207: =AVERAGE(F6:F200) -> 0.0052686853 | G207: =AVERAGE(G6:G200) -> 0.0022541234 | H207: =AVERAGE(H6:H200) -> 0.0041587538 | I207: =AVERAGE(I6:I200) -> 0.012277352 | J207: =AVERAGE(J6:J200) -> -0.0030710666 | K207: =AVERAGE(K6:K200) -> -0.0035277013 | M207: Return | N207: =E207*4 -> -0.032555526 | O207: =F207*4 -> 0.021074741 | P207: =G207*4 -> 0.0090164935 | Q207: =H207*4 -> 0.016635015 | R207: =I207*4 -> 0.049109407 | S207: =J207*4 -> -0.012284267 | T207: =K207*4 -> -0.014110805 | V207: Mean | W207: =E207*52 -> -0.42322184 | X207: =F207*52 -> 0.27397164 | Y207: =G207*52 -> 0.11721442 | Z207: =H207*52 -> 0.2162552 | AA207: =I207*52 -> 0.63842229 | AB207: =J207*52 -> -0.15969547 | AC207: =K207*52 -> -0.18344047
D208: Variance | E208: =_xlfn.VAR.S(E6:E200) -> 0.0094381039 | F208: =_xlfn.VAR.S(F6:F200) -> 0.0048007587 | G208: =_xlfn.VAR.S(G6:G200) -> 0.016775544 | H208: =_xlfn.VAR.S(H6:H200) -> 0.0038176522 | I208: =_xlfn.VAR.S(I6:I200) -> 0.0088230143 | J208: =_xlfn.VAR.S(J6:J200) -> 0.0098250112 | K208: =_xlfn.VAR.S(K6:K200) -> 0.0031326741 | M208: Variance | N208: =E208*4 -> 0.037752415 | O208: =F208*4 -> 0.019203035 | P208: =G208*4 -> 0.067102177 | Q208: =H208*4 -> 0.015270609 | R208: =I208*4 -> 0.035292057 | S208: =J208*4 -> 0.039300045 | T208: =K208*4 -> 0.012530697 | V208: Variance | W208: =E208*52 -> 0.4907814 | X208: =F208*52 -> 0.24963945 | Y208: =G208*52 -> 0.8723283 | Z208: =H208*52 -> 0.19851792 | AA208: =I208*52 -> 0.45879674 | AB208: =J208*52 -> 0.51090058 | AC208: =K208*52 -> 0.16289906
D209: SD | E209: =SQRT(E208) -> 0.097149904 | F209: =SQRT(F208) -> 0.069287507 | G209: =SQRT(G208) -> 0.12952044 | H209: =SQRT(H208) -> 0.061787153 | I209: =SQRT(I208) -> 0.093930902 | J209: =SQRT(J208) -> 0.099121194 | K209: =SQRT(K208) -> 0.055970297 | M209: SD | N209: =E209*4 -> 0.38859962 | O209: =F209*4 -> 0.27715003 | P209: =G209*4 -> 0.51808176 | Q209: =H209*4 -> 0.24714861 | R209: =I209*4 -> 0.37572361 | S209: =J209*4 -> 0.39648478 | T209: =K209*4 -> 0.22388119 | V209: SD | W209: =E209*52 -> 5.051795 | X209: =F209*52 -> 3.6029504 | Y209: =G209*52 -> 6.7350628 | Z209: =H209*52 -> 3.2129319 | AA209: =I209*52 -> 4.8844069 | AB209: =J209*52 -> 5.1543021 | AC209: =K209*52 -> 2.9104554

Sheet Optimum Portfolio 
C3: Variance Coveriance Matrix | N3: Matrix Inverse
D4: SNAP | E4: CRWD | F4: COIN | G4: UBER | H4: PLTR | I4: ROKU | J4: ZM | O4: SNAP | P4: CRWD | Q4: COIN | R4: UBER | S4: PLTR | T4: ROKU | U4: ZM
C5: SNAP | D5: {=MMULT(TRANSPOSE('Return of volatile stocks'!N6:T200),'Return of volatile stocks'!N6:T200)/(195-1)} -> 0.0094381039 | E5: 0.002315457 | F5: 0.0037599931 | G5: 0.0015440185 | H5: 0.0012471034 | I5: 0.0033082391 | J5: 0.0013680207 | N5: SNAP | O5: {=MINVERSE(_xlfn.ANCHORARRAY(D5))} -> 134.15588 | P5: -53.033806 | Q5: -16.254192 | R5: -9.8840928 | S5: 37.170303 | T5: -32.220566 | U5: -4.9448203
C6: CRWD | D6: 0.002315457 | E6: 0.0048007587 | F6: 0.0037986977 | G6: 0.0020580368 | H6: 0.0036334587 | I6: 0.0031261637 | J6: 0.0016730783 | N6: CRWD | O6: -53.033806 | P6: 366.92917 | Q6: -3.415728 | R6: -79.615967 | S6: -100.0781 | T6: -10.807034 | U6: -38.550963
C7: COIN | D7: 0.0037599931 | E7: 0.0037986977 | F7: 0.016775544 | G7: 0.0038789751 | H7: 0.006280371 | I7: 0.0064787934 | J7: 0.0033662724 | N7: COIN | O7: -16.254192 | P7: -3.415728 | Q7: 100.93357 | R7: -42.87188 | S7: -35.203024 | T7: -20.61112 | U7: -29.172438
C8: UBER | D8: 0.0015440185 | E8: 0.0020580368 | F8: 0.0038789751 | G8: 0.0038176522 | H8: 0.0026607828 | I8: 0.0027435416 | J8: 0.001559943 | N8: UBER | O8: -9.8840928 | P8: -79.615967 | Q8: -42.87188 | R8: 416.70287 | S8: -28.56229 | T8: -22.579432 | U8: -68.892405
C9: PLTR | D9: 0.0012471034 | E9: 0.0036334587 | F9: 0.006280371 | G9: 0.0026607828 | H9: 0.0088230143 | I9: 0.0050216597 | J9: 0.002503977 | N9: PLTR | O9: 37.170303 | P9: -100.0781 | Q9: -35.203024 | R9: -28.56229 | S9: 222.63983 | T9: -51.471285 | U9: -36.550878
C10: ROKU | D10: 0.0033082391 | E10: 0.0031261637 | F10: 0.0064787934 | G10: 0.0027435416 | H10: 0.0050216597 | I10: 0.0098250112 | J10: 0.0031733373 | N10: ROKU | O10: -32.220566 | P10: -10.807034 | Q10: -20.61112 | R10: -22.579432 | S10: -51.471285 | T10: 195.87779 | U10: -104.04487
C11: ZM | D11: 0.0013680207 | E11: 0.0016730783 | F11: 0.0033662724 | G11: 0.001559943 | H11: 0.002503977 | I11: 0.0031733373 | J11: 0.0031326741 | N11: ZM | O11: -4.9448203 | P11: -38.550963 | Q11: -29.172438 | R11: -68.892405 | S11: -36.550878 | T11: -104.04487 | U11: 542.22876
N13: Vector | O13: 1 | P13: 1 | Q13: 1 | R13: 1 | S13: 1 | T13: 1 | U13: 1
C16: Global Minimum Variance Portfolio
D18: Proportion | E18: {=MMULT(O13:U13,_xlfn.ANCHORARRAY(O5))/SUM(MMULT(O13:U13,_xlfn.ANCHORARRAY(O5)))} -> 0.11545489 | F18: 0.17096623 | G18: -0.097830987 | H18: 0.3449594 | I18: 0.016680464 | J18: -0.096280866 | K18: 0.54605087
D20: Mean | E20: ='Return of volatile stocks'!W207 -> -0.42322184 | F20: ='Return of volatile stocks'!X207 -> 0.27397164 | G20: ='Return of volatile stocks'!Y207 -> 0.11721442 | H20: ='Return of volatile stocks'!Z207 -> 0.2162552 | I20: ='Return of volatile stocks'!AA207 -> 0.63842229 | J20: ='Return of volatile stocks'!AB207 -> -0.15969547 | K20: ='Return of volatile stocks'!AC207 -> -0.18344047
D22: Return | E22: =SUMPRODUCT(E20:K20,_xlfn.ANCHORARRAY(E18)) -> -0.013034104
D23: Variance | E23: {=MMULT(_xlfn.ANCHORARRAY(E18),MMULT(_xlfn.ANCHORARRAY(D5),TRANSPOSE(_xlfn.ANCHORARRAY(E18))))} -> 0.0020996111
D24: SD | E24: =SQRT(E23) -> 0.045821514
C27: Efficient Portfolio 2
D29: Mean | F29: S^-1*E® | H29: Allocated Weight
D30: =E20 -> -0.42322184 | F30: {=MMULT(_xlfn.ANCHORARRAY(O5),D30:D36)} -> -45.56726 | H30: =F30/SUM(_xlfn.ANCHORARRAY($F$30)) -> 7.3402454
D31: =F20 -> 0.27397164 | F31: 50.261061 | H31: =F31/SUM(_xlfn.ANCHORARRAY($F$30)) -> -8.0963508
D32: =G20 -> 0.11721442 | F32: -5.328568 | H32: =F32/SUM(_xlfn.ANCHORARRAY($F$30)) -> 0.85835744
D33: =H20 -> 0.2162552 | F33: 65.468291 | H33: =F33/SUM(_xlfn.ANCHORARRAY($F$30)) -> -10.546022
D34: =I20 -> 0.63842229 | F34: 103.60998 | H34: =F34/SUM(_xlfn.ANCHORARRAY($F$30)) -> -16.690112
D35: =J20 -> -0.15969547 | F35: -41.678383 | H35: =F35/SUM(_xlfn.ANCHORARRAY($F$30)) -> 6.713802
D36: =K20 -> -0.18344047 | F36: -132.97298 | H36: =F36/SUM(_xlfn.ANCHORARRAY($F$30)) -> 21.42008
G39: Total | H39: =SUM(H30:H36) -> 1
D42: Return | E42: =SUMPRODUCT(D30:D36,H30:H36) -> -23.161555
D43: Variance | E43: {=MMULT(TRANSPOSE(H30:H36),MMULT(_xlfn.ANCHORARRAY(D5),H30:H36))} -> 3.7310011
D44: SD | E44: =SQRT(E43) -> 1.93158
D48: Sharpe Ratio | E48: =E42/E44 -> -11.99099

Sheet Combined Portfolio Returns 
C3: RETURNS | S3: Excess Return
C4: APPLE | D4: NVIDIA | E4: Microsoft | F4: GOOGLE | G4: TESLA | H4: AMAZON | I4: META | J4: SNAP | K4: CRWD | L4: COIN | M4: UBER | N4: PLTR | O4: ROKU | P4: ZM | S4: APPLE | T4: NVIDIA | U4: Microsoft | V4: GOOGLE | W4: TESLA | X4: AMAZON | Y4: META | Z4: SNAP | AA4: CRWD | AB4: COIN | AC4: UBER | AD4: PLTR | AE4: ROKU | AF4: ZM
C6: -0.063572135 | D6: -0.14215902 | E6: -0.04675645 | F6: -0.067698081 | G6: -0.10616431 | H6: -0.12813619 | I6: -0.090540014 | J6: -0.16915935 | K6: -0.070145609 | L6: -0.18087063 | M6: -0.14408348 | N6: -0.16830408 | O6: -0.096128523 | P6: -0.078509949 | S6: =C6-C$203 -> -0.065360153 | T6: =D6-D$203 -> -0.1519885 | U6: =E6-E$203 -> -0.049315804 | V6: =F6-F$203 -> -0.07040743 | W6: =G6-G$203 -> -0.10702109 | X6: =H6-H$203 -> -0.12961583 | Y6: =I6-I$203 -> -0.094405602 | Z6: =J6-J$203 -> -0.16102047 | ... AF6: =P6-P$203 -> -0.074982247
C7: 0.04761373 | D7: -0.022939764 | E7: 0.040482782 | F7: 0.02275411 | G7: -0.10906483 | H7: 0.0093504275 | I7: -0.0048274132 | J7: -0.054378602 | K7: 0.024999054 | L7: -0.077917898 | M7: -0.020520748 | N7: -0.062520357 | O7: -0.0059335617 | P7: -0.02641935 | S7: =C7-C$203 -> 0.045825712 | T7: =D7-D$203 -> -0.03276924 | U7: =E7-E$203 -> 0.037923428 | V7: =F7-F$203 -> 0.020044762 | W7: =G7-G$203 -> -0.10992161 | X7: =H7-H$203 -> 0.0078707878 | Y7: =I7-I$203 -> -0.0086930005 | Z7: =J7-J$203 -> -0.046239721 | ... AF7: =P7-P$203 -> -0.022891648
